/home/bingxing2/home/scx6503/.conda/envs/py39/lib/python3.9/site-packages/bitsandbytes/cuda_setup/main.py:136: UserWarning: /home/bingxing2/home/scx6503/.conda/envs/py39 did not contain libcudart.so as expected! Searching further paths...
  warn(msg)
/home/bingxing2/home/scx6503/.conda/envs/py39/lib/python3.9/site-packages/bitsandbytes/cuda_setup/main.py:136: UserWarning: /home/bingxing2/apps/cudnn/8.6.0.163_cuda11.x/lib:/home/bingxing2/apps/cudnn/8.6.0.163_cuda11.x/lib64:/home/bingxing2/apps/compilers/gcc/12.2.0/lib64:/home/bingxing2/apps/compilers/gcc/12.2.0/lib:/home/bingxing2/apps/compilers/gcc/12.2.0/libexec did not contain libcudart.so as expected! Searching further paths...
  warn(msg)
/home/bingxing2/home/scx6503/.conda/envs/py39/lib/python3.9/site-packages/bitsandbytes/cuda_setup/main.py:136: UserWarning: WARNING: The following directories listed in your path were found to be non-existent: {PosixPath('compilers/gcc/12.2.0&as|compilers/default&as|compilers/latest&as|compilers/gcc/default&as|compilers/gcc/latest')}
  warn(msg)
/home/bingxing2/home/scx6503/.conda/envs/py39/lib/python3.9/site-packages/bitsandbytes/cuda_setup/main.py:136: UserWarning: WARNING: The following directories listed in your path were found to be non-existent: {PosixPath('compilers/gcc/12.2.0&compilers/gcc'), PosixPath('cudnn/8.6.0.163_cuda11.x&cudnn')}
  warn(msg)
/home/bingxing2/home/scx6503/.conda/envs/py39/lib/python3.9/site-packages/bitsandbytes/cuda_setup/main.py:136: UserWarning: WARNING: The following directories listed in your path were found to be non-existent: {PosixPath('/tmp/vscode-git-7e66f8e777.sock')}
  warn(msg)
/home/bingxing2/home/scx6503/.conda/envs/py39/lib/python3.9/site-packages/bitsandbytes/cuda_setup/main.py:136: UserWarning: WARNING: The following directories listed in your path were found to be non-existent: {PosixPath('compilers/gcc/12.2.0'), PosixPath('cudnn/8.6.0.163_cuda11.x')}
  warn(msg)
/home/bingxing2/home/scx6503/.conda/envs/py39/lib/python3.9/site-packages/bitsandbytes/cuda_setup/main.py:136: UserWarning: WARNING: The following directories listed in your path were found to be non-existent: {PosixPath('module use --append /home/bingxing2/apps/tools/modules/modulefiles')}
  warn(msg)
/home/bingxing2/home/scx6503/.conda/envs/py39/lib/python3.9/site-packages/bitsandbytes/cuda_setup/main.py:136: UserWarning: WARNING: The following directories listed in your path were found to be non-existent: {PosixPath('/tmp/vscode-ipc-764cef2b-8cd6-42ed-8cd1-c62d2a699c93.sock')}
  warn(msg)
/home/bingxing2/home/scx6503/.conda/envs/py39/lib/python3.9/site-packages/bitsandbytes/cuda_setup/main.py:136: UserWarning: WARNING: The following directories listed in your path were found to be non-existent: {PosixPath('() {  eval "$(/usr/bin/tclsh \'/home/bingxing2/apps/tools/modules/libexec/modulecmd.tcl\' bash "$@")";\n _mlstatus=$?;\n return $_mlstatus\n}')}
  warn(msg)

===================================BUG REPORT===================================
Welcome to bitsandbytes. For bug reports, please submit your error trace to: https://github.com/TimDettmers/bitsandbytes/issues
================================================================================
CUDA_SETUP: WARNING! libcudart.so not found in any environmental path. Searching /usr/local/cuda/lib64...
CUDA SETUP: CUDA runtime path found: /usr/local/cuda/lib64/libcudart.so
CUDA SETUP: Highest compute capability among GPUs detected: 8.0
CUDA SETUP: Detected CUDA version 116
CUDA SETUP: Loading binary /home/bingxing2/home/scx6503/.conda/envs/py39/lib/python3.9/site-packages/bitsandbytes/libbitsandbytes_cuda116.so...
Training Alpaca-LoRA model with params:
base_model: Linly-Chinese-LLaMA-7B
data_path: /home/bingxing2/home/scx6503/yx/LaWGPT/data/train_info_and_repot.json
output_dir: ./outputs/Linly-Chinese-LLaMA-7B-info_and_repot
batch_size: 64
micro_batch_size: 1
num_epochs: 4
learning_rate: 0.0001
cutoff_len: 600
val_set_size: 0
lora_r: 8
lora_alpha: 32
lora_dropout: 0.05
lora_target_modules: ['q_proj', 'v_proj', 'k_proj', 'o_proj', 'gate_proj', 'down_proj', 'up_proj']
train_on_inputs: True
add_eos_token: True
group_by_length: True
wandb_project: 
wandb_run_name: 
wandb_watch: 
wandb_log_model: 
resume_from_checkpoint: False
prompt template: alpaca

Traceback (most recent call last):
  File "/home/bingxing2/home/scx6503/.conda/envs/py39/lib/python3.9/site-packages/transformers/utils/hub.py", line 417, in cached_file
    resolved_file = hf_hub_download(
  File "/home/bingxing2/home/scx6503/.conda/envs/py39/lib/python3.9/site-packages/huggingface_hub/utils/_validators.py", line 118, in _inner_fn
    return fn(*args, **kwargs)
  File "/home/bingxing2/home/scx6503/.conda/envs/py39/lib/python3.9/site-packages/huggingface_hub/file_download.py", line 1291, in hf_hub_download
    raise LocalEntryNotFoundError(
huggingface_hub.utils._errors.LocalEntryNotFoundError: Connection error, and we cannot find the requested files in the disk cache. Please try again or make sure your Internet connection is on.

During handling of the above exception, another exception occurred:

Traceback (most recent call last):
  File "/home/bingxing2/home/scx6503/yx/LaWGPT/train_clm.py", line 259, in <module>
    fire.Fire(train)
  File "/home/bingxing2/home/scx6503/.conda/envs/py39/lib/python3.9/site-packages/fire/core.py", line 141, in Fire
    component_trace = _Fire(component, args, parsed_flag_args, context, name)
  File "/home/bingxing2/home/scx6503/.conda/envs/py39/lib/python3.9/site-packages/fire/core.py", line 466, in _Fire
    component, remaining_args = _CallAndUpdateTrace(
  File "/home/bingxing2/home/scx6503/.conda/envs/py39/lib/python3.9/site-packages/fire/core.py", line 681, in _CallAndUpdateTrace
    component = fn(*varargs, **kwargs)
  File "/home/bingxing2/home/scx6503/yx/LaWGPT/train_clm.py", line 108, in train
    model = LlamaForCausalLM.from_pretrained(
  File "/home/bingxing2/home/scx6503/.conda/envs/py39/lib/python3.9/site-packages/transformers/modeling_utils.py", line 2259, in from_pretrained
    config, model_kwargs = cls.config_class.from_pretrained(
  File "/home/bingxing2/home/scx6503/.conda/envs/py39/lib/python3.9/site-packages/transformers/configuration_utils.py", line 547, in from_pretrained
    config_dict, kwargs = cls.get_config_dict(pretrained_model_name_or_path, **kwargs)
  File "/home/bingxing2/home/scx6503/.conda/envs/py39/lib/python3.9/site-packages/transformers/configuration_utils.py", line 574, in get_config_dict
    config_dict, kwargs = cls._get_config_dict(pretrained_model_name_or_path, **kwargs)
  File "/home/bingxing2/home/scx6503/.conda/envs/py39/lib/python3.9/site-packages/transformers/configuration_utils.py", line 629, in _get_config_dict
    resolved_config_file = cached_file(
  File "/home/bingxing2/home/scx6503/.conda/envs/py39/lib/python3.9/site-packages/transformers/utils/hub.py", line 452, in cached_file
    raise EnvironmentError(
OSError: We couldn't connect to 'https://huggingface.co' to load this file, couldn't find it in the cached files and it looks like Linly-Chinese-LLaMA-7B is not the path to a directory containing a file named config.json.
Checkout your internet connection or see how to run the library in offline mode at 'https://huggingface.co/docs/transformers/installation#offline-mode'.
